Workbook

Sheet ДАШБОРД
A1: ВЫПОЛНЕНИЕ ГОС.ЗАДАНИЯ 2026 ГОД
B2: план (включая отклонение - 10%) | C2: факт | D2: процент выполнения | E2: остаток
A3: ППК | B3: =ППК!K4-ППК!K8 -> 52502.4 | C3: =ППК!K5 -> 5000 | D3: =C3/B3*100 -> 9.5233742 | E3: =B3-C3 -> 47502.4
A4: Проф.переподготовка | B4: ='ПРОФ.ПЕРЕПОДГОТОВКА'!L4-'ПРОФ.ПЕРЕПОДГОТОВКА'!L8 -> 18192.6 | C4: ='ПРОФ.ПЕРЕПОДГОТОВКА'!L5 -> 0 | D4: =C4/B4*100 -> 0 | E4: =B4-C4 -> 18192.6
A5: Мероприятия | B5: ='МЕРОПРИЯТИЯ'!L5-'МЕРОПРИЯТИЯ'!L9 -> 98.1 | C5: ='МЕРОПРИЯТИЯ'!L6 -> 0 | D5: =C5/B5*100 -> 0 | E5: =B5-C5 -> 98.1
A6: Оценка компетенций | B6: ='ОЦЕНКА КОМПЕТЕНЦИЙ'!K4-'ОЦЕНКА КОМПЕТЕНЦИЙ'!K8 -> 90 | C6: ='ОЦЕНКА КОМПЕТЕНЦИЙ'!K5 -> 0 | D6: =C6/B6*100 -> 0 | E6: =B6-C6 -> 90

Sheet ППК
A1: 1 КВАРТАЛ (1 января - 31 марта)
A2: Полное наименование программы (количество акад. часов) | B2: Сокр название | C2: № группы | D2: Получатели услуг | E2: Количество человек | F2: Кол-во часов | G2: Итого (ч/ч) | H2: Комментарий
G3: =E3*F3 -> 0 | J3: ЭТОТ РАЗДЕЛ НЕ ТРОГАТЬ!
G4: =E4*F4 -> 0 | J4: Всего гз по ППК: | K4: 58336
G5: =E5*F5 -> 0 | J5: ФАКТ (Сейчас): | K5: =G37+G75+G113+G151+G189 -> 5000
G6: =E6*F6 -> 0 | J6: Процент выпонения: | K6: =K5/K4*100 -> 8.5710368
G7: =E7*F7 -> 0 | J7: Остаток: | K7: =K4-K5 -> 53336
E8: 1000 | F8: 5 | G8: =E8*F8 -> 5000 | J8: Отклонение 10% за год | K8: 5833.6
G9: =E9*F9 -> 0
G10: =E10*F10 -> 0
G11: =E11*F11 -> 0 | J11: ПОДИТОГ по программам нарастающим итогом
G12: =E12*F12 -> 0
G13: =E13*F13 -> 0 | J13: Название программы сокращ. | K13: Общее кол-во человек | L13: кол-во групп | M13: общее кол-во чел/часов
G14: =E14*F14 -> 0
G15: =E15*F15 -> 0
G16: =E16*F16 -> 0
G17: =E17*F17 -> 0
G18: =E18*F18 -> 0
G19: =E19*F19 -> 0
G20: =E20*F20 -> 0
G21: =E21*F21 -> 0
G22: =E22*F22 -> 0
G23: =E23*F23 -> 0
G24: =E24*F24 -> 0
G25: =E25*F25 -> 0
... G36: =E36*F36 -> 0
D37: ИТОГ | E37: =SUM(E3:E36) -> 1000 | F37: =SUM(F3:F36) -> 5 | G37: =SUM(G3:G36) -> 5000
A39: 2 КВАРТАЛ (1 апреля - 30 июня)
A40: Полное наименование программы (количество акад. часов) | B40: Сокр название | C40: № группы | D40: Получатели услуг | E40: Количество человек | F40: Кол-во часов | G40: Итого (ч/ч) | H40: Комментарий
G41: =E41*F41 -> 0
G42: =E42*F42 -> 0
G43: =E43*F43 -> 0
G44: =E44*F44 -> 0
G45: =E45*F45 -> 0
G46: =E46*F46 -> 0
G47: =E47*F47 -> 0
G48: =E48*F48 -> 0
G49: =E49*F49 -> 0
G50: =E50*F50 -> 0
G51: =E51*F51 -> 0
...

Sheet ПРОФ.ПЕРЕПОДГОТОВКА
A1: 1 КВАРТАЛ (1 января - 31 марта)
A2: Полное наименование программы (количество акад. часов) | B2: Сокращ название | C2: № группы | D2: Получатели услуг | E2: Количество человек | F2: Кол-во часов | G2: Итого (ч/ч) | H2: Комментарий
G3: =E3*F3 -> 0 | K3: ЭТОТ РАЗДЕЛ НЕ ТРОГАТЬ!
G4: =E4*F4 -> 0 | K4: Всего гз по ПППК: | L4: 20214
G5: =E5*F5 -> 0 | K5: ФАКТ (Сейчас): | L5: =G25+G51+G77+G103+G129 -> 0
G6: =E6*F6 -> 0 | K6: Процент выпонения: | L6: =L5/L4*100 -> 0
G7: =E7*F7 -> 0 | K7: Остаток: | L7: =L4-L5 -> 20214
G8: =E8*F8 -> 0 | K8: Отклонение 10% за год | L8: 2021.4
G9: =E9*F9 -> 0
G10: =E10*F10 -> 0
G11: =E11*F11 -> 0
G12: =E12*F12 -> 0
G13: =E13*F13 -> 0
G14: =E14*F14 -> 0 | J14: ПОДИТОГ по программам нарастающим итогом
G15: =E15*F15 -> 0
G16: =E16*F16 -> 0 | J16: Название программы сокращ. | K16: Общее кол-во человек | L16: кол-во групп | M16: общее кол-во чел/часов
G17: =E17*F17 -> 0
G18: =E18*F18 -> 0
G19: =E19*F19 -> 0
G20: =E20*F20 -> 0
G21: =E21*F21 -> 0
G22: =E22*F22 -> 0
G23: =E23*F23 -> 0
G24: =E24*F24 -> 0
D25: ИТОГ | E25: =SUM(E3:E24) -> 0 | F25: =SUM(F3:F24) -> 0 | G25: =SUM(G3:G24) -> 0
A27: 2 КВАРТАЛ (1 апреля - 30 июня)
A28: Полное наименование программы (количество акад. часов) | C28: № группы | D28: Получатели услуг | E28: Количество человек | F28: Кол-во часов | G28: Итого (ч/ч) | H28: Комментарий
G29: =E29*F29 -> 0
G30: =E30*F30 -> 0
G31: =E31*F31 -> 0
G32: =E32*F32 -> 0
G33: =E33*F33 -> 0
G34: =E34*F34 -> 0
G35: =E35*F35 -> 0
G36: =E36*F36 -> 0
G37: =E37*F37 -> 0
G38: =E38*F38 -> 0
G39: =E39*F39 -> 0
G40: =E40*F40 -> 0
... G50: =E50*F50 -> 0
...

Sheet МЕРОПРИЯТИЯ
A1: 1 КВАРТАЛ (1 января - 31 марта)
A2: Дата | B2: Полное наименование мероприятия (форма+название) | C2: Заказчик (если нет - пишем ЦСО) | D2: Целевая аудитория(получатели услуг) в соответсвии с гос. заданием | E2: Фактическое кол-во участников (по листу регистрации) | F2: Ответственный | G2: Итого мероприятий, шт (ставим цифру 1) | H2: Комментарий
K4: ЭТОТ РАЗДЕЛ НЕ ТРОГАТЬ!
K5: Всего ГЗ по мероприятиям: | L5: 109
K6: Сейчас: | L6: =G45+G91+G137+G183+G229 -> 0
K7: Процент выпонения: | L7: =L6/L5*100 -> 0
K8: Остаток: | L8: =L5-L6 -> 109
K9: Отклонение 10% за год | L9: 10.9
D45: ИТОГ | E45: =SUM(E3:E44) -> 0 | G45: =SUM(G3:G44) -> 0
A47: 2 КВАРТАЛ (1 апреля - 30 июня)
A48: Дата | B48: Полное наименование мероприятия (форма+название) | C48: Заказчик (если нет - пишем ЦСО) | D48: Целевая аудитория в соответсвии с гос. заданием | E48: Фактическое кол-во участников (по листу регистрации) | F48: Ответственный | G48: Итого мероприятий, шт (ставим цифру 1) | H48: Комментарий
D91: ИТОГ | E91: =SUM(E49:E90) -> 0 | G91: =SUM(G49:G90) -> 0
A93: 3 КВАРТАЛ (1 июля - 30 сентября)
A94: Дата | B94: Полное наименование мероприятия (форма+название) | C94: Заказчик (если нет - пишем ЦСО) | D94: Целевая аудитория в соответсвии с гос. заданием | E94: Фактическое кол-во участников (по листу регистрации) | F94: Ответственный | G94: Итого мероприятий, шт (ставим цифру 1) | H94: Комментарий
D137: ИТОГ | E137: =SUM(E95:E136) -> 0 | G137: =SUM(G95:G136) -> 0
A139: 4 КВАРТАЛ (1 октября - 30 ноября)
A140: Дата | B140: Полное наименование мероприятия (форма+название) | C140: Заказчик (если нет - пишем ЦСО) | D140: Целевая аудитория в соответсвии с гос. заданием | E140: Фактическое кол-во участников (по листу регистрации) | F140: Ответственный | G140: Итого мероприятий, шт (ставим цифру 1) | H140: Комментарий
D183: ИТОГ | E183: =SUM(E141:E182) -> 0 | G183: =SUM(G141:G182) -> 0
A185: 4 КВАРТАЛ (1 декабря - 31 декабря)
A186: Дата | B186: Полное наименование мероприятия (форма+название) | C186: Заказчик (если нет - пишем ЦСО) | D186: Целевая аудитория в соответсвии с гос. заданием | E186: Фактическое кол-во участников (по листу регистрации) | F186: Ответственный | G186: Итого мероприятий, шт (ставим цифру 1) | H186: Комментарий
D229: ИТОГ | E229: =SUM(E187:E228) -> 0 | G229: =SUM(G187:G228) -> 0

Sheet ОЦЕНКА КОМПЕТЕНЦИЙ
A1: 1 КВАРТАЛ (1 января - 31 марта)
A2: Наименование методики | B2: Для кого проводим (ведомство) | C2: Участники - Структурное подразделение (если есть) отдел, управление | D2: Целевая аудитория (получатели услуг) | E2: Фактическое кол-во участников (по листу регистрации) ЧЕЛ | F2: Итого мероприятий , шт (ставим цифру 1) | G2: Комментарий
J3: ЭТОТ РАЗДЕЛ НЕ ТРОГАТЬ!
J4: Всего ГЗ по мероприятиям: | K4: 100
J5: Сейчас: | K5: =F44+F89+F134+F179+F224 -> 0
J6: Процент выпонения: | K6: =K5/K4*100 -> 0
J7: Остаток: | K7: =K4-K5 -> 100
J8: Отклонение 10% за год | K8: 10
D44: ИТОГО ЗА КВАРТАЛ | E44: =SUM(E3:E43) -> 0 | F44: =SUM(F3:F43) -> 0
A46: 2 КВАРТАЛ (1 апреля - 30 июня)
A47: Наименование методики | B47: Для кого проводим (ведомство) | C47: Участники - Структурное подразделение (если есть) отдел, управление | D47: Целевая аудитория (получатели услуг) | E47: Фактическое кол-во участников (по листу регистрации) ЧЕЛ | F47: Итого мероприятий , шт (ставим цифру 1) | G47: Комментарий
D89: ИТОГО ЗА КВАРТАЛ | E89: =SUM(E48:E88) -> 0 | F89: =SUM(F48:F88) -> 0
A91: 3 КВАРТАЛ (1 июля - 30 сентября)
A92: Наименование методики | B92: Для кого проводим (ведомство) | C92: Участники - Структурное подразделение (если есть) отдел, управление | D92: Целевая аудитория (получатели услуг) | E92: Фактическое кол-во участников (по листу регистрации) ЧЕЛ | F92: Итого мероприятий , шт (ставим цифру 1) | G92: Комментарий
D134: ИТОГО ЗА КВАРТАЛ | E134: =SUM(E93:E133) -> 0 | F134: =SUM(F93:F133) -> 0
A136: 4 КВАРТАЛ (1 октября - 30 ноября)
A137: Наименование методики | B137: Для кого проводим (ведомство) | C137: Участники - Структурное подразделение (если есть) отдел, управление | D137: Целевая аудитория (получатели услуг) | E137: Фактическое кол-во участников (по листу регистрации) ЧЕЛ | F137: Итого мероприятий , шт (ставим цифру 1) | G137: Комментарий
D179: ИТОГО ЗА КВАРТАЛ | E179: =SUM(E138:E178) -> 0 | F179: =SUM(F138:F178) -> 0
A181: 4 КВАРТАЛ (1 декабря - 31 декабря)
A182: Наименование методики | B182: Для кого проводим (ведомство) | C182: Участники - Структурное подразделение (если есть) отдел, управление | D182: Целевая аудитория (получатели услуг) | E182: Фактическое кол-во участников (по листу регистрации) ЧЕЛ | F182: Итого мероприятий , шт (ставим цифру 1) | G182: Комментарий
D224: ИТОГО ЗА КВАРТАЛ | E224: =SUM(E183:E223) -> 0 | F224: =SUM(F183:F223) -> 0

Sheet данные для выпад списка
A4: Целевая аудитория ДЛЯ МЕРОПРИЯТИЙ | C4: Целевая аудитория ДЛЯ ОЦЕНКИ КОМПЕТЕНЦИЙ
A5: лица, замещающие государственные должности Калужской области | C5: лица, замещающие государственные должности Калужской области
A6: лица, замещающие муниципальные должности | C6: государственные гражданские служащие Калужской области
A7: муниципальные служащие муниципальных образований Калужской области | C7: лица, замещающие муниципальные должности,
A8: лица, включенные в резерв управленческих кадров | C8: муниципальные служащие муниципальных образований Калужской области
A9: работники органов исполнительной власти Калужской области и работники государственных учреждений и предприятий Калужской области | C9: лица, включенные в резерв управленческих кадров
A10: лица проходящие обучение или завершившие обучение в рамках Государственного плана | C10: работники органов исполнительной власти Калужской области и работники государственных учреждений и предприятий Калужской области
A11: участники проекта «Герои земли Калужской» | C11: лица проходящие обучение или завершившие обучение в рамках Государственного плана
A12: по заявке ОИВа | C12: участники проекта «Герои земли Калужской»
C13: по заявке ОИВа
A14: Целевая аудитория ДЛЯ профпереподготовки | C14: Целевая аудитория ДЛЯ ППК
A15: лица, замещающие государственные должности Калужской области | C15: лица, замещающие государственные должности Калужской области
A16: государственные гражданские служащие Калужской области | C16: государственные гражданские служащие Калужской области
A17: муниципальные служащие муниципальных образований Калужской области | C17: лица, замещающие муниципальные должности
A18: участники проекта «Герои земли Калужской» | C18: муниципальные служащие муниципальных образований Калужской области
C19: лица, включенные в резерв управленческих кадров
C20: работники органов исполнительной власти Калужской области и работники государственных учреждений и предприятий Калужской области
C21: лица проходящие обучение или завершившие обучение в рамках Государственного плана
C22: участники проекта «Герои земли Калужской»
