Workbook

Sheet ДАШБОРД
A1: ВЫПОЛНЕНИЕ ГОС.ЗАДАНИЯ 2026 ГОД
B2: план (включая отклонение - 10%) | C2: факт | D2: процент выполнения | E2: остаток
A3: ППК | B3: =ППК!I4-ППК!I8 -> 52502.4 | C3: =ППК!I5 -> 10000 | D3: =ППК!I6 -> 17.142074 | E3: =ППК!I7 -> 48336
A4: Проф.переподготовка | B4: ='ПРОФ.ПЕРЕПОДГОТОВКА'!J4-'ПРОФ.ПЕРЕПОДГОТОВКА'!J8 -> 18192.6 | C4: ='ПРОФ.ПЕРЕПОДГОТОВКА'!J5 -> 0 | D4: ='ПРОФ.ПЕРЕПОДГОТОВКА'!J6 -> 0 | E4: ='ПРОФ.ПЕРЕПОДГОТОВКА'!J7 -> 20214
A5: Мероприятия | B5: =МЕРОПРИЯТИЯ!L5-МЕРОПРИЯТИЯ!L9 -> 98.1 | C5: =МЕРОПРИЯТИЯ!L6 -> 0 | D5: =МЕРОПРИЯТИЯ!L7 -> 0 | E5: =МЕРОПРИЯТИЯ!L8 -> 109
A6: Оценка компетенций | B6: ='ОЦЕНКА КОМПЕТЕНЦИЙ'!J4-'ОЦЕНКА КОМПЕТЕНЦИЙ'!J8 -> 90 | C6: ='ОЦЕНКА КОМПЕТЕНЦИЙ'!J5 -> 0 | D6: ='ОЦЕНКА КОМПЕТЕНЦИЙ'!J6 -> 0 | E6: ='ОЦЕНКА КОМПЕТЕНЦИЙ'!J7 -> 100

Sheet ППК
A1: 1 КВАРТАЛ (1 января - 31 марта)
A2: Полное наименование программы (количество акад. часов) | B2: № группы | C2: Количество человек | D2: Кол-во часов | E2: Итого (ч/ч) | F2: Комментарий
E3: =C3*D3 -> 0 | H3: ЭТОТ РАЗДЕЛ НЕ ТРОГАТЬ!
E4: =C4*D4 -> 0 | H4: Всего гз по ППК: | I4: 58336
E5: =C5*D5 -> 0 | H5: ФАКТ (Сейчас): | I5: =10000 -> 10000
E6: =C6*D6 -> 0 | H6: Процент выпонения: | I6: =I5/I4*100 -> 17.142074
E7: =C7*D7 -> 0 | H7: Остаток: | I7: =I4-I5 -> 48336
E8: =C8*D8 -> 0 | H8: Отклонение 10% за год | I8: =I4*0.1 -> 5833.6
E9: =C9*D9 -> 0
E10: =C10*D10 -> 0
E11: =C11*D11 -> 0 | H11: можно ли без подитога по программам? (чтобы таблицу никто не редачил)
E12: =C12*D12 -> 0
E13: =C13*D13 -> 0
E14: =C14*D14 -> 0
E15: =C15*D15 -> 0
E16: =C16*D16 -> 0
E17: =C17*D17 -> 0
E18: =C18*D18 -> 0
E19: =C19*D19 -> 0
E20: =C20*D20 -> 0
E21: =C21*D21 -> 0
E22: =C22*D22 -> 0
E23: =C23*D23 -> 0
... E36: =C36*D36 -> 0
B37: ИТОГ | C37: =SUM(C3:C36) -> 0 | D37: =SUM(D3:D36) -> 0 | E37: =SUM(E3:E36) -> 0
A39: 2 КВАРТАЛ (1 апреля - 30 июня)
A40: Полное наименование программы (количество акад. часов) | B40: № группы | C40: Количество человек | D40: Кол-во часов | E40: Итого (ч/ч) | F40: Комментарий
E41: =C41*D41 -> 0
E42: =C42*D42 -> 0
E43: =C43*D43 -> 0
E44: =C44*D44 -> 0
E45: =C45*D45 -> 0
E46: =C46*D46 -> 0
E47: =C47*D47 -> 0
E48: =C48*D48 -> 0
E49: =C49*D49 -> 0
E50: =C50*D50 -> 0
E51: =C51*D51 -> 0
E52: =C52*D52 -> 0
... E74: =C74*D74 -> 0
...

Sheet ПРОФ.ПЕРЕПОДГОТОВКА
A1: 1 КВАРТАЛ (1 января - 31 марта)
A2: Полное наименование программы (количество акад. часов) | B2: № группы | C2: Количество человек | D2: Кол-во часов | E2: Итого (ч/ч) | F2: Комментарий
E3: =C3*D3 -> 0 | I3: ЭТОТ РАЗДЕЛ НЕ ТРОГАТЬ!
E4: =C4*D4 -> 0 | I4: Всего гз по ПППК: | J4: 20214
E5: =C5*D5 -> 0 | I5: ФАКТ (Сейчас): | J5: =E25+E51+E77+E103+E129 -> 0
E6: =C6*D6 -> 0 | I6: Процент выпонения: | J6: =J5/J4*100 -> 0
E7: =C7*D7 -> 0 | I7: Остаток: | J7: =J4-J5 -> 20214
E8: =C8*D8 -> 0 | I8: Отклонение 10% за год | J8: =J4*0.1 -> 2021.4
E9: =C9*D9 -> 0
E10: =C10*D10 -> 0 | H10: можно ли без подитога? (чтобы таблицу никто не редачил)
E11: =C11*D11 -> 0
E12: =C12*D12 -> 0
E13: =C13*D13 -> 0
E14: =C14*D14 -> 0
E15: =C15*D15 -> 0
E16: =C16*D16 -> 0
E17: =C17*D17 -> 0
E18: =C18*D18 -> 0
E19: =C19*D19 -> 0
E20: =C20*D20 -> 0
E21: =C21*D21 -> 0
E22: =C22*D22 -> 0
... E24: =C24*D24 -> 0
B25: ИТОГ | C25: =SUM(C3:C24) -> 0 | D25: =SUM(D3:D24) -> 0 | E25: =SUM(E3:E24) -> 0
A27: 2 КВАРТАЛ (1 апреля - 30 июня)
A28: Полное наименование программы (количество акад. часов) | B28: № группы | C28: Количество человек | D28: Кол-во часов | E28: Итого (ч/ч) | F28: Комментарий
E29: =C29*D29 -> 0
E30: =C30*D30 -> 0
E31: =C31*D31 -> 0
E32: =C32*D32 -> 0
E33: =C33*D33 -> 0
E34: =C34*D34 -> 0
E35: =C35*D35 -> 0
E36: =C36*D36 -> 0
E37: =C37*D37 -> 0
E38: =C38*D38 -> 0
E39: =C39*D39 -> 0
E40: =C40*D40 -> 0
... E50: =C50*D50 -> 0
B51: ИТОГ | C51: =SUM(C29:C50) -> 0 | D51: =SUM(D29:D50) -> 0 | E51: =SUM(E29:E50) -> 0
...

Sheet МЕРОПРИЯТИЯ
A1: 1 КВАРТАЛ (1 января - 31 марта)
A2: Дата | B2: Полное наименование мероприятия (форма+название) | C2: Заказчик | D2: Целевая аудитория в соответсвии с гос. заданием | E2: Фактическое кол-во участников (по листу регистрации) | F2: Ответственный | G2: Итого, шт | H2: Комментарий
K4: ЭТОТ РАЗДЕЛ НЕ ТРОГАТЬ!
K5: Всего ГЗ по мероприятиям: | L5: 109
K6: Сейчас: | L6: =G45+G91+G137+G183+G229 -> 0
K7: Процент выпонения: | L7: =L6/L5*100 -> 0
K8: Остаток: | L8: =L5-L6 -> 109
K9: Отклонение 10% за год | L9: =L5*0.1 -> 10.9
D45: ИТОГ | E45: =SUM(E3:E44) -> 0 | G45: =SUM(G3:G44) -> 0
A47: 2 КВАРТАЛ (1 апреля - 30 июня)
A48: Дата | B48: Полное наименование мероприятия (форма+название) | C48: Заказчик | D48: Целевая аудитория в соответсвии с гос. заданием | E48: Фактическое кол-во участников (по листу регистрации) | F48: Ответственный | G48: Итого, шт | H48: Комментарий
D91: ИТОГ | E91: =SUM(E49:E90) -> 0 | G91: =SUM(G49:G90) -> 0
A93: 3 КВАРТАЛ (1 июля - 30 сентября)
A94: Дата | B94: Полное наименование мероприятия (форма+название) | C94: Заказчик | D94: Целевая аудитория в соответсвии с гос. заданием | E94: Фактическое кол-во участников (по листу регистрации) | F94: Ответственный | G94: Итого, шт | H94: Комментарий
D137: ИТОГ | E137: =SUM(E95:E136) -> 0 | G137: =SUM(G95:G136) -> 0
A139: 4 КВАРТАЛ (1 октября - 30 ноября)
A140: Дата | B140: Полное наименование мероприятия (форма+название) | C140: Заказчик | D140: Целевая аудитория в соответсвии с гос. заданием | E140: Фактическое кол-во участников (по листу регистрации) | F140: Ответственный | G140: Итого, шт | H140: Комментарий
D183: ИТОГ | E183: =SUM(E141:E182) -> 0 | G183: =SUM(G141:G182) -> 0
A185: 4 КВАРТАЛ (1 декабря - 31 декабря)
A186: Дата | B186: Полное наименование мероприятия (форма+название) | C186: Заказчик | D186: Целевая аудитория в соответсвии с гос. заданием | E186: Фактическое кол-во участников (по листу регистрации) | F186: Ответственный | G186: Итого, шт | H186: Комментарий
D229: ИТОГ | E229: =SUM(E187:E228) -> 0 | G229: =SUM(G187:G228) -> 0

Sheet ОЦЕНКА КОМПЕТЕНЦИЙ
A1: 1 КВАРТАЛ (1 января - 31 марта)
A2: Наименование методики | B2: Для кого проводим (ведомство) | C2: Участники - Структурное подразделение (если есть) отдел, управление | D2: Фактическое кол-во участников (по листу регистрации) | E2: Итого, шт | F2: Комментарий
I3: ЭТОТ РАЗДЕЛ НЕ ТРОГАТЬ!
I4: Всего ГЗ по мероприятиям: | J4: 100
I5: Сейчас: | J5: =E44+E89+E134+E179+E224 -> 0
I6: Процент выпонения: | J6: =J5/J4*100 -> 0
I7: Остаток: | J7: =J4-J5 -> 100
I8: Отклонение 10% за год | J8: =J4*0.1 -> 10
D44: =SUM(D3:D43) -> 0 | E44: =SUM(E3:E43) -> 0
A46: 2 КВАРТАЛ (1 апреля - 30 июня)
A47: Наименование методики | B47: Для кого проводим (ведомство) | C47: Участники - Структурное подразделение (если есть) отдел, управление | D47: Фактическое кол-во участников (по листу регистрации) | E47: Итого, шт | F47: Комментарий
D89: =SUM(D48:D88) -> 0 | E89: =SUM(E48:E88) -> 0
A91: 3 КВАРТАЛ (1 июля - 30 сентября)
A92: Наименование методики | B92: Для кого проводим (ведомство) | C92: Участники - Структурное подразделение (если есть) отдел, управление | D92: Фактическое кол-во участников (по листу регистрации) | E92: Итого, шт | F92: Комментарий
D134: =SUM(D93:D133) -> 0 | E134: =SUM(E93:E133) -> 0
A136: 4 КВАРТАЛ (1 октября - 30 ноября)
A137: Наименование методики | B137: Для кого проводим (ведомство) | C137: Участники - Структурное подразделение (если есть) отдел, управление | D137: Фактическое кол-во участников (по листу регистрации) | E137: Итого, шт | F137: Комментарий
D179: =SUM(D138:D178) -> 0 | E179: =SUM(E138:E178) -> 0
A181: 4 КВАРТАЛ (1 декабря - 31 декабря)
A182: Наименование методики | B182: Для кого проводим (ведомство) | C182: Участники - Структурное подразделение (если есть) отдел, управление | D182: Фактическое кол-во участников (по листу регистрации) | E182: Итого, шт | F182: Комментарий
D224: =SUM(D183:D223) -> 0 | E224: =SUM(E183:E223) -> 0
